2022-03-18 16:43:01,457 INFO    MainThread:85318 [wandb_setup.py:_flush():75] Loading settings from /Users/AFischer/.config/wandb/settings
2022-03-18 16:43:01,457 INFO    MainThread:85318 [wandb_setup.py:_flush():75] Loading settings from /Users/AFischer/PycharmProjects/cocoon-project/docs/wandb/settings
2022-03-18 16:43:01,457 INFO    MainThread:85318 [wandb_setup.py:_flush():75] Loading settings from environment variables: {}
2022-03-18 16:43:01,457 INFO    MainThread:85318 [wandb_setup.py:_flush():75] Inferring run settings from compute environment: {'program': '<python with no main file>'}
2022-03-18 16:43:01,457 INFO    MainThread:85318 [wandb_init.py:_log_setup():405] Logging user logs to /Users/AFischer/PycharmProjects/cocoon-project/docs/wandb/run-20220318_164301-ztmr6ngw/logs/debug.log
2022-03-18 16:43:01,458 INFO    MainThread:85318 [wandb_init.py:_log_setup():406] Logging internal logs to /Users/AFischer/PycharmProjects/cocoon-project/docs/wandb/run-20220318_164301-ztmr6ngw/logs/debug-internal.log
2022-03-18 16:43:01,458 INFO    MainThread:85318 [wandb_init.py:_jupyter_setup():355] configuring jupyter hooks <wandb.sdk.wandb_init._WandbInit object at 0x7f910afc54f0>
2022-03-18 16:43:01,458 INFO    MainThread:85318 [wandb_init.py:init():439] calling init triggers
2022-03-18 16:43:01,459 INFO    MainThread:85318 [wandb_init.py:init():442] wandb.init called with sweep_config: {}
config: {}
2022-03-18 16:43:01,459 INFO    MainThread:85318 [wandb_init.py:init():458] re-initializing run, found existing run on stack: 15ag1izl
2022-03-18 16:43:01,469 ERROR   MainThread:85318 [wandb_init.py:init():981] error
Traceback (most recent call last):
  File "/Users/AFischer/opt/anaconda3/envs/ai_medicine/lib/python3.8/site-packages/wandb/sdk/wandb_init.py", line 954, in init
    run = wi.init()
  File "/Users/AFischer/opt/anaconda3/envs/ai_medicine/lib/python3.8/site-packages/wandb/sdk/wandb_init.py", line 471, in init
    self._wl._global_run_stack[-1].finish()
  File "/Users/AFischer/opt/anaconda3/envs/ai_medicine/lib/python3.8/site-packages/wandb/sdk/wandb_run.py", line 1538, in finish
    tel.feature.finish = True
  File "/Users/AFischer/opt/anaconda3/envs/ai_medicine/lib/python3.8/site-packages/wandb/sdk/lib/telemetry.py", line 43, in __exit__
    self._run._telemetry_callback(self._obj)
  File "/Users/AFischer/opt/anaconda3/envs/ai_medicine/lib/python3.8/site-packages/wandb/sdk/wandb_run.py", line 470, in _telemetry_callback
    self._telemetry_flush()
  File "/Users/AFischer/opt/anaconda3/envs/ai_medicine/lib/python3.8/site-packages/wandb/sdk/wandb_run.py", line 481, in _telemetry_flush
    self._backend.interface._publish_telemetry(self._telemetry_obj)
  File "/Users/AFischer/opt/anaconda3/envs/ai_medicine/lib/python3.8/site-packages/wandb/sdk/interface/interface_shared.py", line 73, in _publish_telemetry
    self._publish(rec)
  File "/Users/AFischer/opt/anaconda3/envs/ai_medicine/lib/python3.8/site-packages/wandb/sdk/interface/interface_queue.py", line 49, in _publish
    raise Exception("The wandb backend process has shutdown")
Exception: The wandb backend process has shutdown
2022-03-18 16:43:34,238 ERROR   MainThread:85318 [wandb_init.py:init():981] error
Traceback (most recent call last):
  File "/Users/AFischer/opt/anaconda3/envs/ai_medicine/lib/python3.8/site-packages/wandb/sdk/wandb_init.py", line 951, in init
    wi.setup(kwargs)
  File "/Users/AFischer/opt/anaconda3/envs/ai_medicine/lib/python3.8/site-packages/wandb/sdk/wandb_init.py", line 143, in setup
    tel.feature.set_init_tags = True
  File "/Users/AFischer/opt/anaconda3/envs/ai_medicine/lib/python3.8/site-packages/wandb/sdk/lib/telemetry.py", line 43, in __exit__
    self._run._telemetry_callback(self._obj)
  File "/Users/AFischer/opt/anaconda3/envs/ai_medicine/lib/python3.8/site-packages/wandb/sdk/wandb_run.py", line 470, in _telemetry_callback
    self._telemetry_flush()
  File "/Users/AFischer/opt/anaconda3/envs/ai_medicine/lib/python3.8/site-packages/wandb/sdk/wandb_run.py", line 481, in _telemetry_flush
    self._backend.interface._publish_telemetry(self._telemetry_obj)
  File "/Users/AFischer/opt/anaconda3/envs/ai_medicine/lib/python3.8/site-packages/wandb/sdk/interface/interface_shared.py", line 73, in _publish_telemetry
    self._publish(rec)
  File "/Users/AFischer/opt/anaconda3/envs/ai_medicine/lib/python3.8/site-packages/wandb/sdk/interface/interface_queue.py", line 49, in _publish
    raise Exception("The wandb backend process has shutdown")
Exception: The wandb backend process has shutdown
2022-03-18 16:46:43,608 INFO    MainThread:85318 [wandb_run.py:_atexit_cleanup():1702] got exitcode: 0
2022-03-18 16:46:43,643 INFO    MainThread:85318 [wandb_run.py:_restore():1674] restore
