2022-03-22 13:46:53,745 INFO    MainThread:88427 [wandb_setup.py:_flush():75] Loading settings from /Users/AFischer/.config/wandb/settings
2022-03-22 13:46:53,746 INFO    MainThread:88427 [wandb_setup.py:_flush():75] Loading settings from /Users/AFischer/PycharmProjects/cocoon-project/docs/wandb/settings
2022-03-22 13:46:53,746 INFO    MainThread:88427 [wandb_setup.py:_flush():75] Loading settings from environment variables: {}
2022-03-22 13:46:53,746 INFO    MainThread:88427 [wandb_setup.py:_flush():75] Inferring run settings from compute environment: {'program': '<python with no main file>'}
2022-03-22 13:46:53,746 INFO    MainThread:88427 [wandb_init.py:_log_setup():405] Logging user logs to /Users/AFischer/PycharmProjects/cocoon-project/docs/wandb/run-20220322_134653-uob5y5xu/logs/debug.log
2022-03-22 13:46:53,746 INFO    MainThread:88427 [wandb_init.py:_log_setup():406] Logging internal logs to /Users/AFischer/PycharmProjects/cocoon-project/docs/wandb/run-20220322_134653-uob5y5xu/logs/debug-internal.log
2022-03-22 13:46:53,746 INFO    MainThread:88427 [wandb_init.py:init():439] calling init triggers
2022-03-22 13:46:53,746 INFO    MainThread:88427 [wandb_init.py:init():442] wandb.init called with sweep_config: {}
config: {}
2022-03-22 13:46:53,746 INFO    MainThread:88427 [wandb_init.py:init():458] re-initializing run, found existing run on stack: 3ii8ryyd
2022-03-22 13:46:53,767 ERROR   MainThread:88427 [wandb_init.py:init():981] error
Traceback (most recent call last):
  File "/Users/AFischer/opt/anaconda3/envs/ai_medicine/lib/python3.8/site-packages/wandb/sdk/wandb_init.py", line 954, in init
    run = wi.init()
  File "/Users/AFischer/opt/anaconda3/envs/ai_medicine/lib/python3.8/site-packages/wandb/sdk/wandb_init.py", line 471, in init
    self._wl._global_run_stack[-1].finish()
  File "/Users/AFischer/opt/anaconda3/envs/ai_medicine/lib/python3.8/site-packages/wandb/sdk/wandb_run.py", line 1538, in finish
    tel.feature.finish = True
  File "/Users/AFischer/opt/anaconda3/envs/ai_medicine/lib/python3.8/site-packages/wandb/sdk/lib/telemetry.py", line 43, in __exit__
    self._run._telemetry_callback(self._obj)
  File "/Users/AFischer/opt/anaconda3/envs/ai_medicine/lib/python3.8/site-packages/wandb/sdk/wandb_run.py", line 470, in _telemetry_callback
    self._telemetry_flush()
  File "/Users/AFischer/opt/anaconda3/envs/ai_medicine/lib/python3.8/site-packages/wandb/sdk/wandb_run.py", line 481, in _telemetry_flush
    self._backend.interface._publish_telemetry(self._telemetry_obj)
  File "/Users/AFischer/opt/anaconda3/envs/ai_medicine/lib/python3.8/site-packages/wandb/sdk/interface/interface_shared.py", line 73, in _publish_telemetry
    self._publish(rec)
  File "/Users/AFischer/opt/anaconda3/envs/ai_medicine/lib/python3.8/site-packages/wandb/sdk/interface/interface_queue.py", line 49, in _publish
    raise Exception("The wandb backend process has shutdown")
Exception: The wandb backend process has shutdown
2022-03-22 13:46:55,844 INFO    MainThread:88427 [wandb_init.py:_pause_backend():318] pausing backend
2022-03-22 13:46:55,845 INFO    MainThread:88427 [jupyter.py:save_ipynb():374] not saving jupyter notebook
2022-03-22 13:47:47,520 INFO    MainThread:88427 [wandb_run.py:_atexit_cleanup():1702] got exitcode: 0
2022-03-22 13:47:47,584 INFO    MainThread:88427 [wandb_run.py:_restore():1674] restore
